<?xml version="1.0"?>  
<robot name="colibri_base">  
	<link name="base_link">  
		<visual>  
	  		<geometry>  
	    		<box size="1.05 0.7 0.210"/>  
	  		</geometry>  
	  		<material name="white">  
	     		<color rgba="0.7 0.7 0.7 .5"/>  
			</material>
			<origin rpy="0 0 0" xyz="0 0 0.123" />  
		</visual>  
	</link>  

	<link name="active_tyer_left">  
		<visual>  
	  		<geometry>  
	   			<cylinder length=".04" radius="0.1005"></cylinder>  
	  		</geometry>  
	  		<material name="black">  
	      		<color rgba="0.1 0.1 0.1 0.8"/>  
	  		</material>    
		</visual>  
	</link>  

	<link name="active_tyer_right">  
		<visual>  
	  		<geometry>  
	   			<cylinder length=".04" radius="0.1005"></cylinder>  
	  		</geometry>  
	  		<material name="black">  
	      		<color rgba="0.1 0.1 0.1 0.8"/>  
	  		</material>      
		</visual>  
	</link> 

	<joint name="base_to_active_tyer_left" type="continuous">  
		<origin rpy="1.57075  0  0" xyz="0  0.276  0.018"/>  
		<parent link="base_link"/>  
		<child link="active_tyer_left"/>      
		<axis xyz="0 0 1"/>  
	</joint>  

	<joint name="base_to_active_tyer_right" type="continuous">  
		<origin rpy="1.57075  0  0" xyz="0  -0.276  0.018"/>  
		<parent link="base_link"/>  
		<child link="active_tyer_right"/>        
		<axis xyz="0 0 1"/>  
	</joint>  

	<link name="passive_tyer_front_left">  
		<visual>  
	  		<geometry>  
	   			<cylinder length=".032" radius="0.049"></cylinder>  
	  		</geometry>  
	  		<material name="black">  
	      		<color rgba="0.3 0.3 0.3 0.6"/>  
	  		</material>    
		</visual>  
	</link>  

	<link name="passive_tyer_front_right">  
		<visual>  
	  		<geometry>  
	   			<cylinder length=".032" radius="0.049"></cylinder>  
	  		</geometry>  
	  		<material name="black">  
	      		<color rgba="0.3 0.3 0.3 0.6"/>  
	  		</material>      
		</visual>  
	</link>  

	<link name="passive_tyer_back_left">  
		<visual>  
	  		<geometry>  
	   			<cylinder length=".032" radius="0.049"></cylinder>  
	  		</geometry>  
	  		<material name="black">  
	      		<color rgba="0.3 0.3 0.3 0.6"/>  
	  		</material>    
		</visual>  
	</link>  

	<link name="passive_tyer_back_right">  
		<visual>  
	  		<geometry>  
	   			<cylinder length=".032" radius="0.049"></cylinder>  
	  		</geometry>  
	  		<material name="black">  
	      		<color rgba="0.3 0.3 0.3 0.6"/>  
	  		</material>    
		</visual>  
	</link>  

	<joint name="base_to_passive_front_left" type="continuous">  
		<origin rpy="1.57075  0  0" xyz="0.285  0.159  0.017"/>  
		<parent link="base_link"/>  
		<child link="passive_tyer_front_left"/>      
		<axis xyz="0 0 1"/>  
	</joint>  

	<joint name="base_to_passive_front_right" type="continuous">  
		<origin rpy="1.57075  0  0" xyz="0.285  -0.159  0.017"/>  
		<parent link="base_link"/>  
		<child link="passive_tyer_front_right"/>        
		<axis xyz="0 0 1"/>  
	</joint>  

	<joint name="base_to_passive_back_left" type="continuous">  
		<origin rpy="1.57075  0  0" xyz="-0.285  0.159  0.017"/>  
		<parent link="base_link"/>  
		<child link="passive_tyer_back_left"/>    
		<axis xyz="0 0 1"/>  
	</joint>  

	<joint name="base_to_passive_back_right" type="continuous">  
		<origin rpy="1.57075  0  0" xyz="-0.285  -0.159  0.017"/>  
		<parent link="base_link"/>  
		<child link="passive_tyer_back_right"/>      
		<axis xyz="0 0 1"/>  
	</joint>

	<link name="mid_layer">  
		<visual>  
	  		<geometry>  
	    		<box size="0.85 0.7 0.100"/>  
	  		</geometry>  
	  		<material name="white">  
	     		<color rgba="0.7 0.7 0.7 .5"/>  
			</material>       
		</visual>  
	</link> 

	<joint name="base_to_mid_layer" type="fixed">  
		<origin rpy="0  0  0" xyz="-0.1  0  0.278"/>  
		<parent link="base_link"/>  
		<child link="mid_layer"/>      
	</joint>  
   
	<link name="top_layer">  
		<visual>  
	  		<geometry>  
	    		<box size="1.05 0.7 0.1"/>  
	  		</geometry>  
	  		<material name="white">  
	     		<color rgba="0.1 0.1 0.1 .5"/>  
			</material>       
		</visual>  
	</link> 

	<joint name="base_to_top_layer" type="fixed">  
		<origin rpy="0  0  0" xyz="0  0  0.378"/>  
		<parent link="base_link"/>  
		<child link="top_layer"/>      
	</joint>  

	<link name="laser">  
		<visual>  
	  		<geometry>  
	   			<cylinder length="0.100" radius="0.04"></cylinder>  
	  		</geometry>  
	  		<material name="yellow">  
	      		<color rgba="1 1 0 0.4"/>  
	  		</material>    
		</visual>  
	</link>  

	<joint name="base_to_laser" type="fixed">  
		<origin rpy="0  0  0" xyz="0.429  0  0.278"/>  
		<parent link="base_link"/>  
		<child link="laser"/>       
	</joint>  

</robot>  
